Workbook

Sheet Quater 3 Contest Batches 
A1: Batch name | B1: Attempt 1 Test Id | C1: Start Date & Time: | D1: End Date & Time | E1: Attempt 2 Test id | F1: Start Date & Time: | G1: End Date & Time | H1: Attempt 3 test ID | I1: Start Date & Time: | J1: End Date & Time | K1: Attempt 4 Test id | L1: Start Date & Time: | M1: End Date & Time
A2: Introduction to Programming (Beginner) 1-Contests Q3 | C2: 9 Sep 2024, Mon, 7:00 am | D2: 23 Sep 2024, Mon, 8:30 am | F2: 23 Sep 2024, Mon, 12:00 am | G2: 7 Oct 2024, Mon, 12:00 am | I2: 7 Oct 2024, Mon, 12:00 am | J2: 21 Oct 2024, Mon, 12:00 am | L2: 45586 | M2: 45647
A3: Introduction to Programming (Beginner) 2-Contests Q3 | C3: 9 Sep 2024, Mon, 7:00 am | D3: 23 Sep 2024, Mon, 8:30 am | F3: 23 Sep 2024, Mon, 12:00 am | G3: 7 Oct 2024, Mon, 12:00 am | I3: 7 Oct 2024, Mon, 12:00 am | J3: 21 Oct 2024, Mon, 12:00 am | L3: 45586 | M3: 45647
A4: Introduction to Problem Solving (Intermediate) 1-Contests Q3 | C4: 9 Sep 2024, Mon, 7:00 am | D4: 23 Sep 2024, Mon, 8:30 am | F4: 23 Sep 2024, Mon, 12:00 am | G4: 7 Oct 2024, Mon, 12:00 am | I4: 7 Oct 2024, Mon, 12:00 am | J4: 21 Oct 2024, Mon, 12:00 am | L4: 45586 | M4: 45647
A5: Introduction to Problem Solving (Intermediate) 2-Contests Q3 | C5: 9 Sep 2024, Mon, 7:00 am | D5: 23 Sep 2024, Mon, 8:30 am | F5: 23 Sep 2024, Mon, 12:00 am | G5: 7 Oct 2024, Mon, 12:00 am | I5: 7 Oct 2024, Mon, 12:00 am | J5: 21 Oct 2024, Mon, 12:00 am | L5: 45586 | M5: 45647
A6: Advanced DSA 1-Contests Q3 | C6: 9 Sep 2024, Mon, 7:00 am | D6: 23 Sep 2024, Mon, 8:30 am | F6: 23 Sep 2024, Mon, 12:00 am | G6: 7 Oct 2024, Mon, 12:00 am | I6: 7 Oct 2024, Mon, 12:00 am | J6: 21 Oct 2024, Mon, 12:00 am | L6: 45586 | M6: 45647
A7: Advanced DSA 2-Contests Q3 | C7: 9 Sep 2024, Mon, 7:00 am | D7: 23 Sep 2024, Mon, 8:30 am | F7: 23 Sep 2024, Mon, 12:00 am | G7: 7 Oct 2024, Mon, 12:00 am | I7: 7 Oct 2024, Mon, 12:00 am | J7: 21 Oct 2024, Mon, 12:00 am | L7: 45586 | M7: 45647
A8: Advanced DSA 3-Contests Q3 | C8: 9 Sep 2024, Mon, 7:00 am | D8: 23 Sep 2024, Mon, 8:30 am | F8: 23 Sep 2024, Mon, 12:00 am | G8: 7 Oct 2024, Mon, 12:00 am | I8: 7 Oct 2024, Mon, 12:00 am | J8: 21 Oct 2024, Mon, 12:00 am | L8: 45586 | M8: 45647
A9: Advanced DSA 4-Contests Q3 | C9: 9 Sep 2024, Mon, 7:00 am | D9: 23 Sep 2024, Mon, 8:30 am | F9: 23 Sep 2024, Mon, 12:00 am | G9: 7 Oct 2024, Mon, 12:00 am | I9: 7 Oct 2024, Mon, 12:00 am | J9: 21 Oct 2024, Mon, 12:00 am | L9: 45586 | M9: 45647
A10: Data Structure Algorithms 1-Contests Q3 | C10: 9 Sep 2024, Mon, 7:00 am | D10: 23 Sep 2024, Mon, 8:30 am | F10: 23 Sep 2024, Mon, 12:00 am | G10: 7 Oct 2024, Mon, 12:00 am | I10: 7 Oct 2024, Mon, 12:00 am | J10: 21 Oct 2024, Mon, 12:00 am | L10: 45586 | M10: 45647
A11: Data Structure Algorithms 2-Contests Q3 | C11: 9 Sep 2024, Mon, 7:00 am | D11: 23 Sep 2024, Mon, 8:30 am | F11: 23 Sep 2024, Mon, 12:00 am | G11: 7 Oct 2024, Mon, 12:00 am | I11: 7 Oct 2024, Mon, 12:00 am | J11: 21 Oct 2024, Mon, 12:00 am | L11: 45586 | M11: 45647
A12: Data Structure Algorithms 3-Contests Q3 | C12: 9 Sep 2024, Mon, 7:00 am | D12: 23 Sep 2024, Mon, 8:30 am | F12: 23 Sep 2024, Mon, 12:00 am | G12: 7 Oct 2024, Mon, 12:00 am | I12: 7 Oct 2024, Mon, 12:00 am | J12: 21 Oct 2024, Mon, 12:00 am | L12: 45586 | M12: 45647
A13: Data Structure Algorithms 4-Contests Q3 | C13: 9 Sep 2024, Mon, 7:00 am | D13: 23 Sep 2024, Mon, 8:30 am | F13: 23 Sep 2024, Mon, 12:00 am | G13: 7 Oct 2024, Mon, 12:00 am | I13: 7 Oct 2024, Mon, 12:00 am | J13: 21 Oct 2024, Mon, 12:00 am | L13: 45586 | M13: 45647
A14: Databases & SQL-Contests Q3 | C14: 9 Sep 2024, Mon, 7:00 am | D14: 23 Sep 2024, Mon, 8:30 am | F14: 23 Sep 2024, Mon, 12:00 am | G14: 7 Oct 2024, Mon, 12:00 am | I14: 7 Oct 2024, Mon, 12:00 am | J14: 45647
A15: Full-stack LLD and Development 1-Contests Q3 | C15: 9 Sep 2024, Mon, 7:00 am | D15: 23 Sep 2024, Mon, 8:30 am | F15: 23 Sep 2024, Mon, 12:00 am | G15: 7 Oct 2024, Mon, 12:00 am | I15: 7 Oct 2024, Mon, 12:00 am | J15: 45647
A16: Full-stack LLD and Development 2-Contests Q3 | C16: 9 Sep 2024, Mon, 7:00 am | D16: 23 Sep 2024, Mon, 8:30 am | F16: 23 Sep 2024, Mon, 12:00 am | G16: 7 Oct 2024, Mon, 12:00 am | I16: 7 Oct 2024, Mon, 12:00 am | J16: 45647
A17: Full-stack LLD and Development 3-Contests Q3 | C17: 9 Sep 2024, Mon, 7:00 am | D17: 23 Sep 2024, Mon, 8:30 am | F17: 23 Sep 2024, Mon, 12:00 am | G17: 7 Oct 2024, Mon, 12:00 am | I17: 7 Oct 2024, Mon, 12:00 am | J17: 45647
A18: Full-stack lld and development 4: Contests Q3 | C18: 9 Sep 2024, Mon, 7:00 am | D18: 23 Sep 2024, Mon, 8:30 am | F18: 23 Sep 2024, Mon, 12:00 am | G18: 7 Oct 2024, Mon, 12:00 am | I18: 7 Oct 2024, Mon, 12:00 am | J18: 45647
A19: Full stack capstone project Contests Q3 | C19: 9 Sep 2024, Mon, 7:00 am | D19: 23 Sep 2024, Mon, 8:30 am | F19: 23 Sep 2024, Mon, 12:00 am | G19: 7 Oct 2024, Mon, 12:00 am | I19: 7 Oct 2024, Mon, 12:00 am | J19: 45647
A20: Backend LLD and Development 1-Contests Q3 | C20: 9 Sep 2024, Mon, 7:00 am | D20: 23 Sep 2024, Mon, 8:30 am | F20: 23 Sep 2024, Mon, 12:00 am | G20: 7 Oct 2024, Mon, 12:00 am | I20: 7 Oct 2024, Mon, 12:00 am | J20: 21 Oct 2024, Mon, 12:00 am | L20: 45586 | M20: 45647
A21: Backend LLD and Development 2-Contests Q3 | C21: 9 Sep 2024, Mon, 7:00 am | D21: 23 Sep 2024, Mon, 8:30 am | F21: 23 Sep 2024, Mon, 12:00 am | G21: 7 Oct 2024, Mon, 12:00 am | I21: 7 Oct 2024, Mon, 12:00 am | J21: 45647
A22: Backend LLD and Development 3-Contests Q3 | C22: 9 Sep 2024, Mon, 7:00 am | D22: 23 Sep 2024, Mon, 8:30 am | F22: 23 Sep 2024, Mon, 12:00 am | G22: 7 Oct 2024, Mon, 12:00 am | I22: 7 Oct 2024, Mon, 12:00 am | J22: 45647
A23: Backend lld and development 4: Contests Q3 | C23: 9 Sep 2024, Mon, 7:00 am | D23: 45605.292
A24: Backend Capstone Project: Contests Q3 | C24: 9 Sep 2024, Mon, 7:00 am | D24: 45605.292
A25: High Level Design-Contests Q3 | C25: 9 Sep 2024, Mon, 7:00 am | D25: 23 Sep 2024, Mon, 8:30 am | F25: 23 Sep 2024, Mon, 12:00 am | G25: 7 Oct 2024, Mon, 12:00 am | I25: 7 Oct 2024, Mon, 12:00 am | J25: 45647
A26: Product Management for Software Engineers-Contests Q3 | C26: 9 Sep 2024, Mon, 7:00 am | D26: 23 Sep 2024, Mon, 8:30 am | F26: 23 Sep 2024, Mon, 12:00 am | G26: 7 Oct 2024, Mon, 12:00 am | I26: 7 Oct 2024, Mon, 12:00 am | J26: 45647
A27: DSA for Competitive Programming-Contests Q3 | C27: 9 Sep 2024, Mon, 7:00 am | D27: 45605.292
A28: Data Engineering-Contests Q3 | C28: 9 Sep 2024, Mon, 7:00 am | D28: 23 Sep 2024, Mon, 8:30 am | F28: 23 Sep 2024, Mon, 12:00 am | G28: 7 Oct 2024, Mon, 12:00 am | I28: 7 Oct 2024, Mon, 12:00 am | J28: 45647
A29: LLD: Practical Software Engineering and Design-Contests Q3 | C29: 9 Sep 2024, Mon, 7:00 am | D29: 23 Sep 2024, Mon, 8:30 am | F29: 23 Sep 2024, Mon, 12:00 am | G29: 7 Oct 2024, Mon, 12:00 am | I29: 7 Oct 2024, Mon, 12:00 am | J29: 45647
A30: Front-end Development-Contests Q3 | C30: 9 Sep 2024, Mon, 7:00 am | D30: 45605.292
A31: Backend Development: Q4 Contest | B31: 45 days | C31: 9 Sep 2024, Mon, 7:00 am | D31: 45646.875
A32: LLD: Object Oriented Design and Analysis-Contests Q3 | C32: 9 Sep 2024, Mon, 7:00 am | D32: 23 Sep 2024, Mon, 8:30 am | F32: 23 Sep 2024, Mon, 12:00 am | G32: 7 Oct 2024, Mon, 12:00 am | I32: 7 Oct 2024, Mon, 12:00 am | J32: 45647
A33: Computer Systems and Fundamentals-Contests Q3 | C33: 9 Sep 2024, Mon, 7:00 am | D33: 23 Sep 2024, Mon, 8:30 am | F33: 23 Sep 2024, Mon, 12:00 am | G33: 7 Oct 2024, Mon, 12:00 am | I33: 7 Oct 2024, Mon, 12:00 am | J33: 21 Oct 2024, Mon, 12:00 am | L33: 45586 | M33: 45647
A34: Backend Development: Q4 Contest extended

Sheet Quater 4 Contest Batches 
A1: Batch names | B1: Start Date & Time: | C1: End Date & Time | D1: Attempt 2 Test id | E1: Start Date & Time: | F1: End Date & Time | G1: Attempt 3 test ID | H1: Start Date & Time: | I1: End Date & Time | J1: Attempt 4 Test id | K1: Start Date & Time: | L1: End Date & Time
A2: Advance Programming Concepts: NV Contest Q1 2026 | B2: 26 Mar 2026, Thu, 9:00 pm | C2: 25 May 2026, Mon, 9:00 pm | E2: 26 May 2026, Tue, 12:00 am | F2: 25 Jul 2026, Sat, 12:00 am | H2: 23 Sep 2026, Wed, 12:00 am | I2: 22 Nov 2026, Sun, 12:00 am | K2: 23 Nov 2026, Mon, 12:00 am | L2: 31 Dec 2026, Thu, 12:00 am
A3: Advance Software Engineering: NV Contest q3 | B3: 45831.875 | C3: 46161.875
A4: Advanced DSA 1: NV B1 Q1 2026 | B4: 20 Jan 2026, Tue, 9:00 pm | C4: 20 Feb 2026, Fri, 10:30 pm | E4: 20 Feb 2026, Fri, 10:30 pm | F4: 20 Mar 2026, Fri, 12:00 am | H4: 20 Mar 2026, Fri, 12:00 am | I4: 20 Apr 2026, Fri, 12:00 am | K4: 20 Apr 2026, Mon, 12:00 am | L4: 20 May 2026, Mon, 12:00 am
A5: Advanced DSA 2: NV B1 Q1 2026 | B5: 20 Jan 2026, Tue, 9:00 pm | C5: 20 Feb 2026, Fri, 10:30 pm | E5: 20 Feb 2026, Fri, 10:30 pm | F5: 20 Mar 2026, Fri, 12:00 am | H5: 20 Mar 2026, Fri, 12:00 am | I5: 20 Apr 2026, Fri, 12:00 am | K5: 20 Apr 2026, Mon, 12:00 am | L5: 20 May 2026, Mon, 12:00 am
A6: Advanced DSA 2: NV Contest June 2026 | B6: 25 May 2026, Mon, 9:00 pm | C6: 3 Jun 2026, Wed, 9:00 pm | E6: 3 Jun 2026, Wed, 12:00 am | F6: 13 Jun 2026, Sat, 12:00 am | H6: 13 Jun 2026, Sat, 12:00 am | I6: 23 Jun 2026, Tue, 12:00 am | K6: 23 Jun 2026, Tue, 12:00 am | L6: 30 Jun 2026, Tue, 12:00 am
A7: Advanced DSA 3: NV B1 Q1 2026 | B7: 20 Jan 2026, Tue, 9:00 pm | C7: 20 Feb 2026, Fri, 10:30 pm | E7: 20 Feb 2026, Fri, 10:30 pm | F7: 20 Mar 2026, Fri, 12:00 am | H7: 20 Mar 2026, Fri, 12:00 am | I7: 20 Apr 2026, Fri, 12:00 am
A8: Advanced DSA 3: NV Contest 2026 May | B8: 46147.875 | C8: 46207.875 | E8: 46208 | F8: 46268
A9: Advanced DSA 4: NV B1 Q1 2026 | B9: 20 Jan 2026, Tue, 9:00 pm | C9: 20 Feb 2026, Fri, 10:30 pm | E9: 20 Feb 2026, Fri, 10:30 pm | F9: 20 Mar 2026, Fri, 12:00 am | H9: 20 Mar 2026, Fri, 12:00 am | I9: 20 Apr 2026, Fri, 12:00 am | K9: 20 Apr 2026, Mon, 12:00 am | L9: 20 May 2026, Mon, 12:00 am
A10: Advanced DSA 4: NV Contest June 2026 | B10: 25 May 2026, Mon, 9:00 pm | C10: 3 Jun 2026, Wed, 9:00 pm | E10: 3 Jun 2026, Wed, 12:00 am | F10: 13 Jun 2026, Sat, 12:00 am | H10: 13 Jun 2026, Sat, 12:00 am | I10: 23 Jun 2026, Tue, 12:00 am | K10: 23 Jun 2026, Tue, 12:00 am | L10: 4 Jul 2026, Sat, 12:00 am
A11: Back-End Development : NV Contest 2026 April | B11: 20 Apr 2026, Mon, 9:00 pm | C11: 46177.875
A12: Back-End Development NV March 2026 Contest | B12: 46111.875 | C12: 46156.875
A13: Backend Capstone Project : NV Contest 2026 April | B13: 46132.875 | C13: 46177.875
A14: Backend Capstone Project: NV B1 Q2 2026 | B14: 46104.875 | C14: 46149.875
A15: Backend development B2 2026 | B15: 46104.875 | C15: 46149.875
A16: Backend LLD and Development 1: NV Contest 2026 Apr | B16: 20 Apr 2026, Mon, 5:00 pm | C16: 20 Apr 2026, Mon, 11:00 pm | E16: 21 Apr 2026, Tue, 12:00 am | F16: 28 Apr 2026, Tue, 12:00 am | H16: 28 Apr 2026, Tue, 12:00 am | I16: 5 May 2026, Tue, 12:00 am | K16: 46147 | L16: 46154
A17: Backend LLD and Development 1: NV Contest 2026 May | B17: 21 May 2026, Thu, 9:00 pm | C17: 21 May 2026, Thu, 11:00 pm | E17: 22 May 2026, Fri, 12:00 am | F17: 29 May 2026, Fri, 12:00 am | H17: 29 May 2026, Fri, 12:00 am | I17: 5 Jun 2026, Fri, 12:00 am | K17: 5 Jun 2026, Fri, 12:00 am | L17: 20 Jul 2026, Mon, 12:00 am
A18: Backend LLD and Development 1: NV Q4 2025 contest | B18: 5 Jan 2026, Mon, 9:00 pm | C18: 5 Feb 2026, Thu, 11:00 pm | E18: 5 Feb 2026, Thu, 11:00 pm | F18: 5 Mar 2026, Thu, 12:00 am | H18: 5 Mar 2026, Thu, 12:00 am | I18: 5 Apr 2026, Thu, 12:00 am | K18: 5 Apr 2026, Sun, 12:00 am | L18: 5 May 2026, Sun, 12:00 am
A19: Backend LLD and Development 2: NV B1 Q1 2026 | B19: 21 Jan 2026, Wed, 9:00 pm | C19: 22 Mar 2026, Sun, 9:00 pm | E19: 23 Mar 2026, Sun, 9:00 pm | F19: 22 May 2026, Fri, 12:00 am | H19: 23 May 2026, Fri, 12:00 am | I19: 22 Jun 2026, Mon, 12:00 am
A20: Backend LLD and Development 3: NV B1 Q1 2026 | B20: 21 Jan 2026, Wed, 9:00 pm | C20: 22 Mar 2026, Sun, 9:00 pm | E20: 23 Mar 2026, Sun, 9:00 pm | F20: 22 May 2026, Fri, 12:00 am | H20: 23 May 2026, Fri, 12:00 am | I20: 22 Jun 2026, Mon, 12:00 am
A21: Backend LLD and Development 3: NV Contest 2026 Apr | B21: 20 Apr 2026, Mon, 9:00 pm | C21: 27 Apr 2026, Mon, 9:00 pm | E21: 27 Apr 2026, Mon, 5:00 am | F21: 4 May 2026, Mon, 12:00 am | H21: 5 Nov 2026, Thu, 12:00 am | I21: 12 Nov 2026, Thu, 12:00 am
A22: Backend LLD and Development 4- NV Contests 2025 dec | B22: 45999.875 | C22: 46120.875
A23: Backend LLD and Development 4- NV Contests 2026 Apr | B23: 46127.875 | C23: 46172.875
A24: Backend LLD and Development 4- NV Contests 2026 May | B24: 46146.583 | C24: 46191.583
A25: Backend Project: NV Contest 2026 May | B25: 46148.875 | C25: 46193.875
A26: Backend Project: NV Contests | B26: 46071.708 | C26: 46116.708
A27: Basics of GenAI and AI agents: NV Contest 2026 May
A28: Computer Systems and Fundamentals: NV B1 Q1 2026 | B28: 21 Jan 2026, Wed, 9:00 pm | C28: 22 Mar 2026, Sun, 9:00 pm | E28: 23 Mar 2026, Sun, 9:00 pm | F28: 22 May 2026, Fri, 12:00 am | H28: 22 May 2026, Fri, 12:00 am | I28: 22 Jun 2026, Mon, 12:00 am | K28: 22 Jun 2026, Mon, 12:00 am | L28: 22 Jul 2026, Wed, 12:00 am
A29: Computer Systems and Fundamentals: NV Contest June 2026 | B29: 25 May 2026, Mon, 9:00 pm | C29: 3 Jun 2026, Wed, 9:00 pm | E29: 3 Jun 2026, Wed, 12:00 am | F29: 13 Jun 2026, Sat, 12:00 am | H29: 13 Jun 2026, Sat, 12:00 am | I29: 23 Jun 2026, Tue, 12:00 am | K29: 23 Jun 2026, Tue, 12:00 am | L29: 4 Jul 2026, Sat, 12:00 am
A30: Data Engineering: NV B1 Q1 2026 | B30: 21 Jan 2026, Wed, 9:00 pm | C30: 22 Mar 2026, Sun, 9:00 pm | E30: 23 Mar 2026, Sun, 9:00 pm | F30: 22 May 2026, Fri, 12:00 am | H30: 22 May 2026, Fri, 12:00 am | I30: 22 Jun 2026, Mon, 12:00 am
A31: Data Engineering: NV Contests 2026 Apr | B31: 20 Apr 2026, Mon, 9:00 pm | C31: 27 Apr 2026, Mon, 9:00 pm | E31: 28 Apr 2026, Tue, 12:00 am | F31: 5 May 2026, Tue, 12:00 am | H31: : 6 May 2026, Wed, 12:00 am | I31: 13 May 2026, Wed, 12:00 am
A32: Data Engineering: NV Contests 2026 May | B32: 13 May 2026, Wed, 9:00 pm | C32: 17 May 2026, Sun, 9:00 pm | E32: 20 May 2026, Wed, 12:00 am | F32: 27 May 2026, Wed, 12:00 am | H32: 26 May 2026, Tue, 12:00 am | I32: 31 May 2026, Sun, 12:00 am
A33: Databases & SQL: NV B1 Q1 2026 | B33: 21 Jan 2026, Wed, 9:00 pm | C33: 22 Mar 2026, Sun, 9:00 pm | E33: 23 Mar 2026, Sun, 9:00 pm | F33: 22 May 2026, Fri, 12:00 am | H33: 23 May 2026, Fri, 12:00 am | I33: 22 Jun 2026, Mon, 12:00 am
A34: DSA 1: NV B1 2026 | B34: 21 Jan 2026, Wed, 9:00 pm | C34: 22 Mar 2026, Sun, 9:00 pm | E34: 23 Mar 2026, Sun, 9:00 pm | F34: 22 May 2026, Fri, 12:00 am | H34: 23 May 2026, Fri, 12:00 am | I34: 22 Jun 2026, Mon, 12:00 am | K34: 22 Jun 2026, Mon, 12:00 am | L34: 22 July 2026, Mon, 12:00 am
A35: DSA 2: NV B1 2026 | B35: 21 Jan 2026, Wed, 9:00 pm | C35: 22 Mar 2026, Sun, 9:00 pm | E35: 23 Mar 2026, Sun, 9:00 pm | F35: 22 May 2026, Fri, 12:00 am | H35: 23 May 2026, Fri, 12:00 am | I35: 22 Jun 2026, Mon, 12:00 am | K35: 22 Jun 2026, Mon, 12:00 am | L35: 22 July 2026, Mon, 12:00 am
A36: DSA 3: NV B1 2026 | B36: 21 Jan 2026, Wed, 9:00 pm | C36: 22 Mar 2026, Sun, 9:00 pm | E36: 23 Mar 2026, Sun, 9:00 pm | F36: 22 May 2026, Fri, 12:00 am | H36: 23 May 2026, Fri, 12:00 am | I36: 22 Jun 2026, Mon, 12:00 am | K36: 22 Jun 2026, Mon, 12:00 am | L36: 22 July 2026, Mon, 12:00 am
A37: DSA 4: NV B1 2026 | B37: 21 Jan 2026, Wed, 9:00 pm | C37: 22 Mar 2026, Sun, 9:00 pm | E37: 23 Mar 2026, Sun, 9:00 pm | F37: 22 May 2026, Fri, 12:00 am | H37: 23 May 2026, Fri, 12:00 am | I37: 22 Jun 2026, Mon, 12:00 am | K37: 22 Jun 2026, Mon, 12:00 am | L37: 22 July 2026, Mon, 12:00 am
A38: DSA 4.2 : NV Contest 2026 April | B38: 28 Apr 2026, Tue, 7:00 pm | C38: 28 Apr 2026, Tue, 11:30 pm | E38: 29 Apr 2026, Wed, 12:00 am | F38: 6 May 2026, Wed, 12:00 am | H38: 6 May 2026, Wed, 12:00 am | I38: 13 May 2026, Wed, 12:00 am | K38: 13 May 2026, Wed, 12:00 am | L38: 27 Jun 2026, Sat, 12:00 am
A39: DSA 4.2: NV Contest B1 2025 | B39: 10 Nov 2025, Mon, 9:00 pm | C39: 10 Dec 2025, Wed, 11:30 pm | E39: 10 Dec 2025, Wed, 11:30 pm | F39: 10 Jan 2026, Sat, 12:00 am | H39: 10 Jan 2026, Sat, 12:00 am | I39: 10 Feb 2026, Tue, 12:00 am | K39: 10 Feb 2026, Tue, 12:00 am | L39: 10 Mar 2026, Tue, 12:00 am
A40: DSA for Competitive Programming : NV Contest 2026 April | B40: 46132.875 | C40: 46177.875
...

Sheet dsml new contests
A1: Module | B1: batch name | C1: Start and End date | D1: Start and End date
A2: ML: Unsupervised and RecSys | B2: ML : Unsupervised and RecSys: NV B1 Q1 2026 | C2: 21 Jan 2026, Wed, 9:00 pm-22 Mar 2026, Sun, 9:00 pm | D2: 23 Mar 2026, Sun, 9:00 pm-22 May 2026, Fri, 12:00 am
A3: Intro to ML and NN | B3: Intro to ML and NN: Q1 2026 B1 | C3: 2 Mar 2026, Mon, 9:00 pm - 2 May 2026, Sat, 11:00 pm | D3: 3 May 2026, Sun, 12:00 am - 3 Jul 2026, Fri, 12:00 am
A4: ML: Adv Supervised Algorithms | B4: ML : Adv Supervised Algorithm: NV B1 Q1 2026 | C4: 21 Jan 2026, Wed, 9:00 pm-22 Mar 2026, Sun, 9:00 pm | D4: 23 Mar 2026, Sun, 9:00 pm-22 May 2026, Fri, 12:00 am
A5: MLOps | B5: MLOps: Q2 2026 NV Contest | C5: 17 Mar 2026, Tue, 9:00 pm- 17 Apr 2026, Fri, 11:59 pm | D5: April 18, 2026 12:00 AM - May 18, 2026 11:59 PM
A6: Common Core Maths | B6: Common Core Maths: NV B1 Q1 2026 | C6: January 21, 2026 09:00 PM - April 22, 2026 11:00 PM
A7: Data Analytics and Visualisation - Fundamentals | B7: Data Analytics and Visualisation - Fundamentals: NV B1 Q1 2026 | C7: 21 Jan 2026, Wed, 9:00 pm-22 Mar 2026, Sun, 9:00 pm | D7: 23 Mar 2026, Sun, 9:00 pm-22 May 2026, Fri, 12:00 am
A8: Product analytics | B8: Product Analytics: NV B1 Q1 2026 | C8: 21 Jan 2026, Wed, 9:00 pm-22 Mar 2026, Sun, 9:00 pm | D8: 23 Mar 2026, Sun, 9:00 pm-22 May 2026, Fri, 12:00 am
A9: Tableau and Excel | B9: Tableau and Excel: NV B1 Q1 2026 | C9: 21 Jan 2026, Wed, 9:00 pm-22 Mar 2026, Sun, 9:00 pm | D9: 23 Mar 2026, Sun, 9:00 pm-22 May 2026, Fri, 12:00 am
A10: Maths for ML | B10: Maths for ML: NV B1 Q1 2026 | C10: 21 Jan 2026, Wed, 9:00 pm-22 Mar 2026, Sun, 9:00 pm | D10: 23 Mar 2026, Sun, 9:00 pm-22 May 2026, Fri, 12:00 am
A11: Neural Networks | B11: Neural Networks: NV B1 Q1 2026 | C11: 21 Jan 2026, Wed, 9:00 pm-22 Mar 2026, Sun, 9:00 pm | D11: 23 Mar 2026, Sun, 9:00 pm-22 May 2026, Fri, 12:00 am
A12: Data Analytics and Visualisation - Python Libraries | B12: Data Analytics and Visualisation - Python Libraries: NV B1 Q1 2026 | C12: 21 Jan 2026, Wed, 9:00 pm-22 Mar 2026, Sun, 9:00 pm | D12: 23 Mar 2026, Sun, 9:00 pm-22 May 2026, Fri, 12:00 am
A13: Common Core Tools | B13: Common Core Tools: Nv Contest may | C13: May 12, 2025 09:00 PM - February 12, 2026 09:00 PM
A14: Common Core Foundations | B14: Common Core Foundations: May 25 contest | C14: May 14, 2025 07:00 AM - January 1, 2026 07:00 AM
A15: SQL | B15: SQL: NV B1 Q1 2026 | C15: 21 Jan 2026, Wed, 9:00 pm-22 Mar 2026, Sun, 9:00 pm | D15: 23 Mar 2026, Sun, 9:00 pm-22 May 2026, Fri, 12:00 am
A16: Beginner Python 1 | B16: Beginner Python 1: NV Contest 2025 | C16: June 11, 2025 09:00 PM - March 31, 2026 09:00 PM
A17: Advanced Python | B17: Advanced Python: NV B1 Q1 2026 | C17: January 21, 2026 09:00 PM - May 22, 2026 11:00 PM
A18: Beginner Python 2 | B18: Beginner Python 2: NV Contest Q2 2026 | C18: March 30, 2026 09:00 PM - May 14, 2026 09:00 PM
A19: Computer Vision | B19: Computer Vision: B1 Contest 2026 | C19: 21 Jan 2026, Wed, 9:00 pm-22 Mar 2026, Sun, 9:00 pm | D19: 23 Mar 2026, Sun, 9:00 pm-22 May 2026, Fri, 12:00 am
A20: Beginner Python 1 | B20: Beginner Python 1: NV B1 Q1 2026 | C20: 21 Jan 2026, Wed, 9:00 pm-22 Mar 2026, Sun, 9:00 pm | D20: 23 Mar 2026, Sun, 9:00 pm-22 May 2026, Fri, 12:00 am
A21: Natural Language Processing | B21: Natural Language Processing: NV B1 Q1 2026 | C21: 21 Jan 2026, Wed, 9:00 pm-22 Mar 2026, Sun, 9:00 pm | D21: 23 Mar 2026, Sun, 9:00 pm-22 May 2026, Fri, 12:00 am
A22: ML : Supervised Algorithms | B22: ML : Supervised Algorithms: NV Contest 2026 Q2 | C22: 6 Apr 2026, Mon, 9:00 pm - 6 May 2026, Wed, 11:00 pm | D22: 7 May 2026, Thu, 12:00 am - 7 Jun 2026, Sun, 12:00 am
A23: Data Analytics and Visualisation - Probability and Stats | B23: DAV: Probability and Statistics NV contest 2026 | C23: 3 Feb 2026, Tue, 9:00 pm - 3 Mar 2026, Tue, 11:59 pm | D23: 3 Mar 2026, Tue, 12:00 am - 3 May 2026, Sun, 11:59 pm
A24: Introduction to Problem Solving (Intermediate) 1 | B24: Introduction to Problem Solving (Intermediate) 1: NV B1 2026 | C24: February 9, 2026 09:00 PM - March 26, 2026 09:00 PM
A25: Common Core Foundations: NV Contest B1 2026 | B25: Common Core Foundations: NV Contest B1 2026 | C25: February 9, 2026 09:00 PM - July 31, 2026 09:00 PM
A26: DA ML 2 | B26: DA ML 2: NV Contest B1 2026 | C26: March 17, 2026 09:00 PM - May 1, 2026 09:00 PM
A27: Neural Networks | B27: Neural Networks | C27: April 6, 2026 09:00 PM - May 21, 2026 09:00 PM
A28: Advanced SQL | B28: Advanced SQL : NV Apr26 Q2 | C28: April 16, 2026 09:00 PM - May 31, 2026 09:00 PM
A29: Tableau and Excel | B29: Tableau and Excel : NV Apr26 Q2 Reattempt 1 | C29: April 16, 2026 09:00 PM - May 31, 2026 09:00 PM
A30: Common Core Maths | B30: Common Core Maths: NV Contest 2026 April | C30: April 27, 2026 09:00 PM - June 11, 2026 09:00 PM
A31: Common Core Tools | B31: Common Core Tools: NV Contest 2026 April | C31: April 27, 2026 09:00 PM - June 11, 2026 09:00 PM
A32: Common Core Foundations | B32: Common Core Foundations: NV Contest 2026 April | C32: April 27, 2026 09:00 PM - June 11, 2026 09:00 PM
A33: Data Analytics and Visualisation - Probability and Stats | B33: DAV: Probability and Statistics NV Contest 2026 May | C33: May 6, 2026 09:00 PM - May 31, 2026 11:00 PM
A34: MLOps | B34: MLOps: NV Contest 2026 May | C34: May 20, 2026 03:25 PM - July 4, 2026 03:25 PM
A35: Classical ML 1 | B35: Classical ML 1: NV Contest May 2026 | C35: 20 May 2026, Wed, 3:35 pm - 27 May 2026, Wed, 5:05 pm | D35: 28 May 2026, Thu, 12:00 am - 4 Jun 2026, Thu, 12:00 am
A36: Introduction to Problem Solving (Intermediate) 1 | B36: Introduction to Problem Solving (Intermediate) 1: NV Contest May 2026 | C36: 23 May 2026, Sat, 7:25 pm-23 May 2026, Sat, 8:55 pm | D36: 24 May 2026, Sun, 12:00 am - 31 May 2026, Sun, 12:00 am | E36: 31 May 2026, Sun, 12:00 am - 7 Jun 2026, Sun, 12:00 am | F36: 7 Jun 2026, Sun, 12:00 am - 22 Jul 2026, Wed, 12:00 am
A37: Data Analytics and Visualisation - Python Libraries | B37: Data Analytics and Visualisation - Python Libraries: NV Contest May 2026 | C37: 23 May 2026, Sat, 12:15 pm - 1 Jun 2026, Mon, 3:14 pm | D37: 2 Jun 2026, Tue, 12:00 am - 16 Jun 2026, Tue, 11:59 pm
A38: Data Analytics and Visualisation - Fundamentals | B38: Data Analytics and Visualisation - Fundamentals: NV Contest May 2026 | C38: May 23, 2026 01:50 PM - July 7, 2026 01:50 PM
A39: Maths for ML | B39: Maths for ML: NV Contest May 2026 | C39: 23 May 2026, Sat, 1:20 pm - 1 Jun 2026, Mon, 4:19 pm | D39: 2 Jun 2026, Tue, 12:00 am - 16 Jun 2026, Tue, 11:59 pm
A40: Advanced Python | B40: Advanced Python: NV Contest June 2026 | C40: May 25, 2026 09:00 PM - July 9, 2026 09:00 PM
...

Sheet Academy New Contests 
A1: NV ACADEMY CONTEST
A2: Module Name | B2: Batch Name | C2: Attempt 1 | E2: Attempt 2 | G2: Attempt 3 | I2: Attempt 4 | K2: No. of Attempts | L2: Final Contest Deadline | M2: Days Remaining | N2: Contest Status
C3: Start Date | D3: End Date | E3: Start Date | F3: End Date | G3: Start Date | H3: End Date | I3: Start Date | J3: End Date
A4: Advanced AI Agents | B4: Advanced AI Agents: NV Contest June 2026 | C4: Isn't available yet
A5: Advance Programming Concepts | B5: =CONCATENATE(A5,": NV Contest June 2026") | C5: 46169.875 | D5: 46177.875 | E5: 46177 | F5: 46184 | G5: 46184 | H5: 46193 | I5: 46193 | J5: 46203 | K5: =COUNT(C5,E5,G5,I5) | L5: =IFERROR(MAX(C5:J5),"") | M5: =IFERROR(IF(L5="","",L5-TODAY()),"") | N5: =IFERROR(IF(L5="","",IF(L5<TODAY(),"Expired",IF(L5-TODAY()<=5,"Expiring Soon","Active"))),"")
A6: Advance Software Engineering | B6: =CONCATENATE(A6,": NV Contest June 2026") | C6: 46169.875 | D6: 46212.875 | K6: =COUNT(C6,E6,G6,I6) | L6: =IFERROR(MAX(C6:J6),"") | M6: =IFERROR(IF(L6="","",L6-TODAY()),"") | N6: =IFERROR(IF(L6="","",IF(L6<TODAY(),"Expired",IF(L6-TODAY()<=5,"Expiring Soon","Active"))),"")
A7: Advanced DSA 1 | B7: =CONCATENATE(A7,": NV Contest June 2026") | C7: 46169.792 | D7: 46177.792 | E7: 46177 | F7: 46184 | G7: 46184 | H7: 46193 | I7: 46193 | J7: 46203 | K7: =COUNT(C7,E7,G7,I7) | L7: =IFERROR(MAX(C7:J7),"") | M7: =IFERROR(IF(L7="","",L7-TODAY()),"") | N7: =IFERROR(IF(L7="","",IF(L7<TODAY(),"Expired",IF(L7-TODAY()<=5,"Expiring Soon","Active"))),"")
A8: Advanced DSA 2 | B8: =CONCATENATE(A8,": NV Contest June 2026") | C8: 46167.875 | D8: 46177.875 | E8: 46177 | F8: 46184 | G8: 46184 | H8: 46193 | I8: 46193 | J8: 46203 | K8: =COUNT(C8,E8,G8,I8) | L8: =IFERROR(MAX(C8:J8),"") | M8: =IFERROR(IF(L8="","",L8-TODAY()),"") | N8: =IFERROR(IF(L8="","",IF(L8<TODAY(),"Expired",IF(L8-TODAY()<=5,"Expiring Soon","Active"))),"")
A9: Advanced DSA 3 | B9: Advanced DSA 3: NV Contest July 2026 | C9: 46188.875 | D9: 46203.875 | E9: 46204 | F9: 46218 | G9: 46218 | H9: 46234 | I9: 46235 | J9: 46244 | K9: =COUNT(C9,E9,G9,I9) | L9: =IFERROR(MAX(C9:J9),"") | M9: =IFERROR(IF(L9="","",L9-TODAY()),"") | N9: =IFERROR(IF(L9="","",IF(L9<TODAY(),"Expired",IF(L9-TODAY()<=5,"Expiring Soon","Active"))),"")
A10: Advanced DSA 4 | B10: =CONCATENATE(A10,": NV Contest June 2026") | C10: 46167.875 | D10: 46177.875 | E10: 46177 | F10: 46184 | G10: 46184 | H10: 46193 | I10: 46193 | J10: 46203 | K10: =COUNT(C10,E10,G10,I10) | L10: =IFERROR(MAX(C10:J10),"") | M10: =IFERROR(IF(L10="","",L10-TODAY()),"") | N10: =IFERROR(IF(L10="","",IF(L10<TODAY(),"Expired",IF(L10-TODAY()<=5,"Expiring Soon","Active"))),"")
A11: Backend Capstone Project | B11: Backend Capstone Project : NV Contest June 2026 | C11: 46169.875 | D11: 46212.875 | K11: =COUNT(C11,E11,G11,I11) | L11: =IFERROR(MAX(C11:J11),"") | M11: =IFERROR(IF(L11="","",L11-TODAY()),"") | N11: =IFERROR(IF(L11="","",IF(L11<TODAY(),"Expired",IF(L11-TODAY()<=5,"Expiring Soon","Active"))),"")
A12: Backend Development | B12: =CONCATENATE(A12,": NV Contest June 2026") | C12: 46171.875 | D12: 46212.875 | K12: =COUNT(C12,E12,G12,I12) | L12: =IFERROR(MAX(C12:J12),"") | M12: =IFERROR(IF(L12="","",L12-TODAY()),"") | N12: =IFERROR(IF(L12="","",IF(L12<TODAY(),"Expired",IF(L12-TODAY()<=5,"Expiring Soon","Active"))),"")
A13: Backend LLD and Development 1 | B13: =CONCATENATE(A13,": NV Contest June 2026") | C13: 46171.875 | D13: 46177.958 | E13: 46177 | F13: 46184 | G13: 46184 | H13: 46193 | I13: 46193 | J13: 46203 | K13: =COUNT(C13,E13,G13,I13) | L13: =IFERROR(MAX(C13:J13),"") | M13: =IFERROR(IF(L13="","",L13-TODAY()),"") | N13: =IFERROR(IF(L13="","",IF(L13<TODAY(),"Expired",IF(L13-TODAY()<=5,"Expiring Soon","Active"))),"")
A14: Backend LLD and Development 2 | B14: =CONCATENATE(A14,": NV Contest June 2026") | C14: 46195.875 | D14: 46203.875 | E14: 46204 | F14: 46211 | G14: 46211 | H14: 46218 | K14: =COUNT(C14,E14,G14,I14) | L14: =IFERROR(MAX(C14:J14),"") | M14: =IFERROR(IF(L14="","",L14-TODAY()),"") | N14: =IFERROR(IF(L14="","",IF(L14<TODAY(),"Expired",IF(L14-TODAY()<=5,"Expiring Soon","Active"))),"")
A15: Backend LLD and Development 3 | B15: =CONCATENATE(A15,": NV Contest June 2026") | C15: 46171.875 | D15: 46183.875 | E15: 46183 | F15: 46193 | G15: 46193 | H15: 46203 | K15: =COUNT(C15,E15,G15,I15) | L15: =IFERROR(MAX(C15:J15),"") | M15: =IFERROR(IF(L15="","",L15-TODAY()),"") | N15: =IFERROR(IF(L15="","",IF(L15<TODAY(),"Expired",IF(L15-TODAY()<=5,"Expiring Soon","Active"))),"")
A16: Backend LLD and Development 4 | B16: =CONCATENATE(A16,": NV Contest June 2026") | C16: 46171.875 | D16: 46212.875 | K16: =COUNT(C16,E16,G16,I16) | L16: =IFERROR(MAX(C16:J16),"") | M16: =IFERROR(IF(L16="","",L16-TODAY()),"") | N16: =IFERROR(IF(L16="","",IF(L16<TODAY(),"Expired",IF(L16-TODAY()<=5,"Expiring Soon","Active"))),"")
A17: Backend Project | B17: =CONCATENATE(A17,": NV Contest June 2026") | C17: 46171.875 | D17: 46212.875 | K17: =COUNT(C17,E17,G17,I17) | L17: =IFERROR(MAX(C17:J17),"") | M17: =IFERROR(IF(L17="","",L17-TODAY()),"") | N17: =IFERROR(IF(L17="","",IF(L17<TODAY(),"Expired",IF(L17-TODAY()<=5,"Expiring Soon","Active"))),"")
A18: Basics of GenAI and AI agents | B18: =CONCATENATE(A18,": NV Contest June 2026") | C18: Isn't available yet
A19: Computer Systems and Fundamentals | B19: =CONCATENATE(A19,": NV Contest June 2026") | C19: 46167.875 | D19: 46176.875 | E19: 46176 | F19: 46186 | G19: 46186 | H19: 46196 | I19: 46196 | J19: 46212 | K19: =COUNT(C19,E19,G19,I19) | L19: =IFERROR(MAX(C19:J19),"") | M19: =IFERROR(IF(L19="","",L19-TODAY()),"") | N19: =IFERROR(IF(L19="","",IF(L19<TODAY(),"Expired",IF(L19-TODAY()<=5,"Expiring Soon","Active"))),"")
A20: Data Engineering | B20: Data Engineering: NV Contest July 2026 | C20: 46195.875 | D20: 46203.875 | E20: 46204 | F20: 46210 | G20: 46210 | H20: 46217 | K20: =COUNT(C20,E20,G20,I20) | L20: =IFERROR(MAX(C20:J20),"") | M20: =IFERROR(IF(L20="","",L20-TODAY()),"") | N20: =IFERROR(IF(L20="","",IF(L20<TODAY(),"Expired",IF(L20-TODAY()<=5,"Expiring Soon","Active"))),"")
A21: Databases & SQL | B21: =CONCATENATE(A21,": NV Contest June 2026") | C21: 46171.875 | D21: 46183.875 | E21: 46183 | F21: 46193 | G21: 46193 | H21: 46203 | K21: =COUNT(C21,E21,G21,I21) | L21: =IFERROR(MAX(C21:J21),"") | M21: =IFERROR(IF(L21="","",L21-TODAY()),"") | N21: =IFERROR(IF(L21="","",IF(L21<TODAY(),"Expired",IF(L21-TODAY()<=5,"Expiring Soon","Active"))),"")
A22: DSA 1 | B22: =CONCATENATE(A22,": NV Contest June 2026") | C22: 46195.875 | D22: 46200.875 | E22: 46201 | F22: 46207 | G22: 46208 | H22: 46214 | I22: 46215 | J22: 46223 | K22: =COUNT(C22,E22,G22,I22) | L22: =IFERROR(MAX(C22:J22),"") | M22: =IFERROR(IF(L22="","",L22-TODAY()),"") | N22: =IFERROR(IF(L22="","",IF(L22<TODAY(),"Expired",IF(L22-TODAY()<=5,"Expiring Soon","Active"))),"")
A23: DSA 2 | B23: =CONCATENATE(A23,": NV Contest June 2026") | C23: 46171.875 | D23: 46183.938 | E23: 46183 | F23: 46193 | G23: 46193 | H23: 46203 | I23: 46203 | J23: 46213 | K23: =COUNT(C23,E23,G23,I23) | L23: =IFERROR(MAX(C23:J23),"") | M23: =IFERROR(IF(L23="","",L23-TODAY()),"") | N23: =IFERROR(IF(L23="","",IF(L23<TODAY(),"Expired",IF(L23-TODAY()<=5,"Expiring Soon","Active"))),"")
A24: DSA 3 | B24: =CONCATENATE(A24,": NV Contest June 2026") | C24: 46171.875 | D24: 46183.938 | E24: 46183 | F24: 46193 | G24: 46193 | H24: 46203 | I24: 46203 | J24: 46213 | K24: =COUNT(C24,E24,G24,I24) | L24: =IFERROR(MAX(C24:J24),"") | M24: =IFERROR(IF(L24="","",L24-TODAY()),"") | N24: =IFERROR(IF(L24="","",IF(L24<TODAY(),"Expired",IF(L24-TODAY()<=5,"Expiring Soon","Active"))),"")
A25: DSA 4 | B25: =CONCATENATE(A25,": NV Contest June 2026") | C25: 46171.875 | D25: 46183.938 | E25: 46183 | F25: 46193 | G25: 46193 | H25: 46203 | I25: 46203 | J25: 46212 | K25: =COUNT(C25,E25,G25,I25) | L25: =IFERROR(MAX(C25:J25),"") | M25: =IFERROR(IF(L25="","",L25-TODAY()),"") | N25: =IFERROR(IF(L25="","",IF(L25<TODAY(),"Expired",IF(L25-TODAY()<=5,"Expiring Soon","Active"))),"")
A26: DSA 4.2 | B26: =CONCATENATE(A26,": NV Contest June 2026") | C26: 46171.875 | D26: 46183.979 | E26: 46183 | F26: 46193 | G26: 46193 | H26: 46203 | I26: 46203 | J26: 46213 | K26: =COUNT(C26,E26,G26,I26) | L26: =IFERROR(MAX(C26:J26),"") | M26: =IFERROR(IF(L26="","",L26-TODAY()),"") | N26: =IFERROR(IF(L26="","",IF(L26<TODAY(),"Expired",IF(L26-TODAY()<=5,"Expiring Soon","Active"))),"")
A27: DSA for Competitive Programming | B27: =CONCATENATE(A27,": NV Contest June 2026") | C27: 46182.875 | D27: 46234.875 | K27: =COUNT(C27,E27,G27,I27) | L27: =IFERROR(MAX(C27:J27),"") | M27: =IFERROR(IF(L27="","",L27-TODAY()),"") | N27: =IFERROR(IF(L27="","",IF(L27<TODAY(),"Expired",IF(L27-TODAY()<=5,"Expiring Soon","Active"))),"")
A28: LLD: Object Oriented Design and Analysis | B28: =CONCATENATE(A28,": NV Contest June 2026") | C28: 46182.875 | D28: 46234.875 | K28: =COUNT(C28,E28,G28,I28) | L28: =IFERROR(MAX(C28:J28),"") | M28: =IFERROR(IF(L28="","",L28-TODAY()),"") | N28: =IFERROR(IF(L28="","",IF(L28<TODAY(),"Expired",IF(L28-TODAY()<=5,"Expiring Soon","Active"))),"")
A29: LLD: Practical Software Engineering and Design | B29: LLD: Practical Software Engineering and Design: NV Contest June 2026 | C29: 46171.812 | D29: 46183.812 | E29: 46183 | F29: 46193 | G29: 46193 | H29: 46203 | K29: =COUNT(C29,E29,G29,I29) | L29: =IFERROR(MAX(C29:J29),"") | M29: =IFERROR(IF(L29="","",L29-TODAY()),"") | N29: =IFERROR(IF(L29="","",IF(L29<TODAY(),"Expired",IF(L29-TODAY()<=5,"Expiring Soon","Active"))),"")
A30: Front-end Development | B30: Front-end Development: NV Contest June 2026 | C30: 46190.875 | D30: 46235.875 | K30: =COUNT(C30,E30,G30,I30) | L30: =IFERROR(MAX(C30:J30),"") | M30: =IFERROR(IF(L30="","",L30-TODAY()),"") | N30: =IFERROR(IF(L30="","",IF(L30<TODAY(),"Expired",IF(L30-TODAY()<=5,"Expiring Soon","Active"))),"")
A31: full-stack capstone | B31: =CONCATENATE(A31,": NV Contest June 2026") | C31: 46182.875 | D31: 46193.875 | E31: 46193 | F31: 46203 | G31: 46203 | H31: 46218 | K31: =COUNT(C31,E31,G31,I31) | L31: =IFERROR(MAX(C31:J31),"") | M31: =IFERROR(IF(L31="","",L31-TODAY()),"") | N31: =IFERROR(IF(L31="","",IF(L31<TODAY(),"Expired",IF(L31-TODAY()<=5,"Expiring Soon","Active"))),"")
A32: Full-stack LLD and Development 1 | B32: =CONCATENATE(A32,": NV Contest June 2026") | C32: 46182.875 | D32: 46193.875 | E32: 46193 | F32: 46203 | G32: 46203 | H32: 46218 | K32: =COUNT(C32,E32,G32,I32) | L32: =IFERROR(MAX(C32:J32),"") | M32: =IFERROR(IF(L32="","",L32-TODAY()),"") | N32: =IFERROR(IF(L32="","",IF(L32<TODAY(),"Expired",IF(L32-TODAY()<=5,"Expiring Soon","Active"))),"")
A33: Full-stack LLD and Development 2 | B33: =CONCATENATE(A33,": NV Contest June 2026") | C33: 46182.875 | D33: 46193.875 | E33: 46193 | F33: 46203 | G33: 46203 | H33: 46218 | K33: =COUNT(C33,E33,G33,I33) | L33: =IFERROR(MAX(C33:J33),"") | M33: =IFERROR(IF(L33="","",L33-TODAY()),"") | N33: =IFERROR(IF(L33="","",IF(L33<TODAY(),"Expired",IF(L33-TODAY()<=5,"Expiring Soon","Active"))),"")
A34: Full-stack LLD and Development 3 | B34: =CONCATENATE(A34,": NV Contest June 2026") | C34: 46182.875 | D34: 46193.875 | E34: 46188.875 | F34: 46203.875 | G34: 46204 | H34: 46218 | I34: 46218 | J34: 46234 | K34: =COUNT(C34,E34,G34,I34) | L34: =IFERROR(MAX(C34:J34),"") | M34: =IFERROR(IF(L34="","",L34-TODAY()),"") | N34: =IFERROR(IF(L34="","",IF(L34<TODAY(),"Expired",IF(L34-TODAY()<=5,"Expiring Soon","Active"))),"")
A35: Full-stack LLD and Development 4 | B35: Full-stack LLD and Development 4: NV Contest June 2026 | C35: 46181.875 | D35: 46188.875 | E35: 46189 | F35: 46203 | K35: =COUNT(C35,E35,G35,I35) | L35: =IFERROR(MAX(C35:J35),"") | M35: =IFERROR(IF(L35="","",L35-TODAY()),"") | N35: =IFERROR(IF(L35="","",IF(L35<TODAY(),"Expired",IF(L35-TODAY()<=5,"Expiring Soon","Active"))),"")
A36: High level design | B36: High level design: NV Contests 2026 June | C36: 46184.875 | D36: 46193.875 | E36: 46193 | F36: 46203 | G36: 46204 | H36: 46213 | K36: =COUNT(C36,E36,G36,I36) | L36: =IFERROR(MAX(C36:J36),"") | M36: =IFERROR(IF(L36="","",L36-TODAY()),"") | N36: =IFERROR(IF(L36="","",IF(L36<TODAY(),"Expired",IF(L36-TODAY()<=5,"Expiring Soon","Active"))),"")
A37: Introduction to Problem Solving (Intermediate) 1 | B37: Introduction to Problem Solving (Intermediate) 1: NV Contest June 2026 | C37: 46171.875 | D37: 46177.938 | E37: 46177 | F37: 46183 | G37: 46183 | H37: 46193 | I37: 46193 | J37: 46203 | K37: =COUNT(C37,E37,G37,I37) | L37: =IFERROR(MAX(C37:J37),"") | M37: =IFERROR(IF(L37="","",L37-TODAY()),"") | N37: =IFERROR(IF(L37="","",IF(L37<TODAY(),"Expired",IF(L37-TODAY()<=5,"Expiring Soon","Active"))),"")
A38: Introduction to Problem Solving (Intermediate) 2 | B38: Introduction to Problem Solving (Intermediate) 2: NV Contest June 2026 | C38: 46181.875 | D38: 46183.875 | E38: 46183 | F38: 46193 | G38: 46193 | H38: 46203 | I38: 46203 | J38: 46213 | K38: =COUNT(C38,E38,G38,I38) | L38: =IFERROR(MAX(C38:J38),"") | M38: =IFERROR(IF(L38="","",L38-TODAY()),"") | N38: =IFERROR(IF(L38="","",IF(L38<TODAY(),"Expired",IF(L38-TODAY()<=5,"Expiring Soon","Active"))),"")
A39: Introduction to Programming (Beginner) 1 | B39: Introduction to Programming (Beginner) 1: NV Contest June 2026 | C39: 46168.875 | D39: 46183.938 | E39: 46183 | F39: 46193 | G39: 46193 | H39: 46200 | I39: 46200 | J39: 46212 | K39: =COUNT(C39,E39,G39,I39) | L39: =IFERROR(MAX(C39:J39),"") | M39: =IFERROR(IF(L39="","",L39-TODAY()),"") | N39: =IFERROR(IF(L39="","",IF(L39<TODAY(),"Expired",IF(L39-TODAY()<=5,"Expiring Soon","Active"))),"")
A40: Introduction to Programming (Beginner) 2 | B40: Introduction to Programming (Beginner) 2: NV Contest June 2026 | C40: 46184.875 | D40: 46193.938 | E40: 46193 | F40: 46203 | G40: 46204 | H40: 46213 | I40: 46213 | J40: 46223 | K40: =COUNT(C40,E40,G40,I40) | L40: =IFERROR(MAX(C40:J40),"") | M40: =IFERROR(IF(L40="","",L40-TODAY()),"") | N40: =IFERROR(IF(L40="","",IF(L40<TODAY(),"Expired",IF(L40-TODAY()<=5,"Expiring Soon","Active"))),"")
...

Sheet Sheet93
A1: Advance Programming Concepts: NV Contest Q1 2026 | B1: =LEFT(A1,FIND(":",A1)-1)
A2: Advance Software Engineering: NV Contest q3 | B2: =LEFT(A2,FIND(":",A2)-1)
A3: Advanced DSA 1: NV B1 Q1 2026 | B3: =LEFT(A3,FIND(":",A3)-1)
A4: Advanced DSA 2: NV B1 Q1 2026 | B4: =LEFT(A4,FIND(":",A4)-1)
A5: Advanced DSA 3: NV B1 Q1 2026 | B5: =LEFT(A5,FIND(":",A5)-1)
A6: Advanced DSA 4: NV B1 Q1 2026 | B6: =LEFT(A6,FIND(":",A6)-1)
A7: Back-End Development: NV March 2026 Contest | B7: =LEFT(A7,FIND(":",A7)-1)
A8: Back-End Development : NV Contest 2026 April | B8: =LEFT(A8,FIND(":",A8)-1)
A9: Backend Capstone Project: NV B1 Q2 2026 | B9: =LEFT(A9,FIND(":",A9)-1)
A10: Backend Capstone Project : NV Contest 2026 April | B10: =LEFT(A10,FIND(":",A10)-1)
A11: Backend development: B2 2026 | B11: =LEFT(A11,FIND(":",A11)-1)
A12: Backend LLD and Development 1: NV Q4 2025 contest | B12: =LEFT(A12,FIND(":",A12)-1)
... A26: DSA for Competitive Programming : NV Contest 2026 April | B26: =LEFT(A26,FIND(":",A26)-1)
A27: Front-end development: NV Contests 2025 Q2 2026 | B27: LLD: Object Oriented Design and Analysis
A28: Front-end development: NV contest B1 2026 | B28: LLD: Practical Software Engineering and Design
A29: full-stack capstone: contest 2025 | B29: =LEFT(A29,FIND(":",A29)-1)
A30: Full-stack LLD and Development 1: NV B1 Q1 2026 | B30: =LEFT(A30,FIND(":",A30)-1)
A31: Full-stack LLD and Development 2: NV B1 Q1 2026 | B31: =LEFT(A31,FIND(":",A31)-1)
B32: Full-stack LLD and Development 3

Sheet DSML Contests
A1: NV DSML CONTEST
A2: Module Name | B2: Batch Name | C2: Attempt 1 | E2: Attempt 2 | G2: Attempt 3 | I2: Attempt 4 | K2: No. of Attempts | L2: Final Contest Deadline | M2: Days Remaining | N2: Contest Status
C3: Start Date | D3: End Date | E3: Start Date | F3: End Date | G3: Start Date | H3: End Date | I3: Start Date | J3: End Date
A4: Advanced Python | B4: Advanced Python: NV Contest June 2026 | C4: 46167.875 | D4: 46212.875 | K4: =COUNT(C4,E4,G4,I4) | L4: =IFERROR(MAX(C4:J4),"") | M4: =IFERROR(IF(L4="","",L4-TODAY()),"") | N4: =IFERROR(IF(L4="","",IF(L4<TODAY(),"Expired",IF(L4-TODAY()<=5,"Expiring Soon","Active"))),"")
A5: Advanced SQL | B5: Advanced SQL: NV Contest 2026 June | C5: 46167.875 | D5: 46212.875 | K5: =COUNT(C5,E5,G5,I5) | L5: =IFERROR(MAX(C5:J5),"") | M5: =IFERROR(IF(L5="","",L5-TODAY()),"") | N5: =IFERROR(IF(L5="","",IF(L5<TODAY(),"Expired",IF(L5-TODAY()<=5,"Expiring Soon","Active"))),"")
A6: Beginner Python 1 | B6: Beginner Python 1: NV Contest 2026 June | C6: 46167.875 | D6: 46212.875 | K6: =COUNT(C6,E6,G6,I6) | L6: =IFERROR(MAX(C6:J6),"") | M6: =IFERROR(IF(L6="","",L6-TODAY()),"") | N6: =IFERROR(IF(L6="","",IF(L6<TODAY(),"Expired",IF(L6-TODAY()<=5,"Expiring Soon","Active"))),"")
A7: Beginner Python 2 | B7: Beginner Python 2: NV Contest 2026 June | C7: 46167.875 | D7: 46212.875 | K7: =COUNT(C7,E7,G7,I7) | L7: =IFERROR(MAX(C7:J7),"") | M7: =IFERROR(IF(L7="","",L7-TODAY()),"") | N7: =IFERROR(IF(L7="","",IF(L7<TODAY(),"Expired",IF(L7-TODAY()<=5,"Expiring Soon","Active"))),"")
A8: Classical ML 1 | B8: Classical ML 1: NV Contest 2026 July | C8: 46188.875 | D8: 46203.938 | E8: 46204 | F8: 46218 | K8: =COUNT(C8,E8,G8,I8) | L8: =IFERROR(MAX(C8:J8),"") | M8: =IFERROR(IF(L8="","",L8-TODAY()),"") | N8: =IFERROR(IF(L8="","",IF(L8<TODAY(),"Expired",IF(L8-TODAY()<=5,"Expiring Soon","Active"))),"")
A9: Classical ML 2 | B9: Classical ML 2: NV Contest 2026 July | C9: 46188.875 | D9: 46203.999 | E9: 46204 | F9: 46218.999 | K9: =COUNT(C9,E9,G9,I9) | L9: =IFERROR(MAX(C9:J9),"") | M9: =IFERROR(IF(L9="","",L9-TODAY()),"") | N9: =IFERROR(IF(L9="","",IF(L9<TODAY(),"Expired",IF(L9-TODAY()<=5,"Expiring Soon","Active"))),"")
A10: Common Core Foundations | B10: Common Core Foundations: NV Contest 2026 June | C10: 46167.875 | D10: 46212.875 | K10: =COUNT(C10,E10,G10,I10) | L10: =IFERROR(MAX(C10:J10),"") | M10: =IFERROR(IF(L10="","",L10-TODAY()),"") | N10: =IFERROR(IF(L10="","",IF(L10<TODAY(),"Expired",IF(L10-TODAY()<=5,"Expiring Soon","Active"))),"")
A11: Common Core Maths | B11: Common Core Maths: NV Contest 2026 June | C11: 46167.875 | D11: 46212.875 | K11: =COUNT(C11,E11,G11,I11) | L11: =IFERROR(MAX(C11:J11),"") | M11: =IFERROR(IF(L11="","",L11-TODAY()),"") | N11: =IFERROR(IF(L11="","",IF(L11<TODAY(),"Expired",IF(L11-TODAY()<=5,"Expiring Soon","Active"))),"")
A12: Common Core Tools | B12: Common Core Tools: NV Contest 2026 June | C12: 46167.875 | D12: 46212.875 | K12: =COUNT(C12,E12,G12,I12) | L12: =IFERROR(MAX(C12:J12),"") | M12: =IFERROR(IF(L12="","",L12-TODAY()),"") | N12: =IFERROR(IF(L12="","",IF(L12<TODAY(),"Expired",IF(L12-TODAY()<=5,"Expiring Soon","Active"))),"")
A13: Computer Vision | B13: Computer Vision: NV Contest 2026 July | C13: 46188.875 | D13: 46203.875 | E13: 46204 | F13: 46213 | G13: 46213 | H13: 46223 | I13: 46223 | J13: 46244 | K13: =COUNT(C13,E13,G13,I13) | L13: =IFERROR(MAX(C13:J13),"") | M13: =IFERROR(IF(L13="","",L13-TODAY()),"") | N13: =IFERROR(IF(L13="","",IF(L13<TODAY(),"Expired",IF(L13-TODAY()<=5,"Expiring Soon","Active"))),"")
A14: DA ML 1 | B14: DA ML 1: NV Contest 2026 July | C14: 46188.875 | D14: 46203.958 | E14: 46204 | F14: 46218 | K14: =COUNT(C14,E14,G14,I14) | L14: =IFERROR(MAX(C14:J14),"") | M14: =IFERROR(IF(L14="","",L14-TODAY()),"") | N14: =IFERROR(IF(L14="","",IF(L14<TODAY(),"Expired",IF(L14-TODAY()<=5,"Expiring Soon","Active"))),"")
A15: DA ML 2 | B15: DA ML 2: NV Contest 2026 June | C15: 46167.875 | D15: 46212.875 | K15: =COUNT(C15,E15,G15,I15) | L15: =IFERROR(MAX(C15:J15),"") | M15: =IFERROR(IF(L15="","",L15-TODAY()),"") | N15: =IFERROR(IF(L15="","",IF(L15<TODAY(),"Expired",IF(L15-TODAY()<=5,"Expiring Soon","Active"))),"")
A16: Data Analytics and Visualisation - Fundamentals | B16: Data Analytics and Visualisation - Fundamentals: NV Contest 2026 June | C16: 46167.875 | D16: 46212.875 | K16: =COUNT(C16,E16,G16,I16) | L16: =IFERROR(MAX(C16:J16),"") | M16: =IFERROR(IF(L16="","",L16-TODAY()),"") | N16: =IFERROR(IF(L16="","",IF(L16<TODAY(),"Expired",IF(L16-TODAY()<=5,"Expiring Soon","Active"))),"")
A17: Data Analytics and Visualisation - Probability and Statistics | B17: Data Analytics and Visualisation - Probability and Statistics: NV Contest 2026 July | C17: 46188.875 | D17: 46203.999 | E17: 46204 | F17: 46218.999 | K17: =COUNT(C17,E17,G17,I17) | L17: =IFERROR(MAX(C17:J17),"") | M17: =IFERROR(IF(L17="","",L17-TODAY()),"") | N17: =IFERROR(IF(L17="","",IF(L17<TODAY(),"Expired",IF(L17-TODAY()<=5,"Expiring Soon","Active"))),"")
A18: Data Analytics and Visualisation - Python Libraries | B18: Data Analytics and Visualisation - Python Libraries: NV Contest July 2026 | C18: 46188.875 | D18: 46203.999 | E18: 46204 | F18: 46218.999 | K18: =COUNT(C18,E18,G18,I18) | L18: =IFERROR(MAX(C18:J18),"") | M18: =IFERROR(IF(L18="","",L18-TODAY()),"") | N18: =IFERROR(IF(L18="","",IF(L18<TODAY(),"Expired",IF(L18-TODAY()<=5,"Expiring Soon","Active"))),"")
A19: Intro to ML and NN | B19: Intro to ML and NN: NV Contest 2026 July | C19: 46188.875 | D19: 46203.958 | E19: 46204 | F19: 46218 | K19: =COUNT(C19,E19,G19,I19) | L19: =IFERROR(MAX(C19:J19),"") | M19: =IFERROR(IF(L19="","",L19-TODAY()),"") | N19: =IFERROR(IF(L19="","",IF(L19<TODAY(),"Expired",IF(L19-TODAY()<=5,"Expiring Soon","Active"))),"")
A20: Introduction to Problem Solving (Intermediate) 1 | B20: Introduction to Problem Solving (Intermediate) 1: NV Contest 2026 June | C20: 46167.875 | D20: 46183.938 | E20: 46183 | F20: 46193 | G20: 46193 | H20: 46200 | I20: 46200 | J20: 46212 | K20: =COUNT(C20,E20,G20,I20) | L20: =IFERROR(MAX(C20:J20),"") | M20: =IFERROR(IF(L20="","",L20-TODAY()),"") | N20: =IFERROR(IF(L20="","",IF(L20<TODAY(),"Expired",IF(L20-TODAY()<=5,"Expiring Soon","Active"))),"")
A21: Introduction to Problem Solving (Intermediate) 2 | B21: Introduction to Problem Solving (Intermediate) 2: NV Contest 2026 June | C21: 46167.875 | D21: 46183.875 | E21: 46183 | F21: 46183 | G21: 46193 | H21: 46200 | I21: 46200 | J21: 46212 | K21: =COUNT(C21,E21,G21,I21) | L21: =IFERROR(MAX(C21:J21),"") | M21: =IFERROR(IF(L21="","",L21-TODAY()),"") | N21: =IFERROR(IF(L21="","",IF(L21<TODAY(),"Expired",IF(L21-TODAY()<=5,"Expiring Soon","Active"))),"")
A22: Maths for ML | B22: Maths for ML: NV Contest 2026 July | C22: 46188.875 | D22: 46203.999 | E22: 46204 | F22: 46218.999 | K22: =COUNT(C22,E22,G22,I22) | L22: =IFERROR(MAX(C22:J22),"") | M22: =IFERROR(IF(L22="","",L22-TODAY()),"") | N22: =IFERROR(IF(L22="","",IF(L22<TODAY(),"Expired",IF(L22-TODAY()<=5,"Expiring Soon","Active"))),"")
A23: ML : Supervised Algorithms | B23: ML : Supervised Algorithms: NV Contest 2026 July | C23: 46188.875 | D23: 46203.999 | E23: 46204 | F23: 46218.999 | K23: =COUNT(C23,E23,G23,I23) | L23: =IFERROR(MAX(C23:J23),"") | M23: =IFERROR(IF(L23="","",L23-TODAY()),"") | N23: =IFERROR(IF(L23="","",IF(L23<TODAY(),"Expired",IF(L23-TODAY()<=5,"Expiring Soon","Active"))),"")
A24: ML: Adv Supervised Algorithms | B24: ML: Adv Supervised Algorithms: NV Contest 2026 July | C24: 46188.875 | D24: 46203.999 | E24: 46204 | F24: 46218.999 | K24: =COUNT(C24,E24,G24,I24) | L24: =IFERROR(MAX(C24:J24),"") | M24: =IFERROR(IF(L24="","",L24-TODAY()),"") | N24: =IFERROR(IF(L24="","",IF(L24<TODAY(),"Expired",IF(L24-TODAY()<=5,"Expiring Soon","Active"))),"")
A25: ML: Unsupervised and RecSys | B25: ML: Unsupervised and RecSys: NV Contest 2026 July | C25: 46188.875 | D25: 46203.999 | E25: 46204 | F25: 46218.999 | K25: =COUNT(C25,E25,G25,I25) | L25: =IFERROR(MAX(C25:J25),"") | M25: =IFERROR(IF(L25="","",L25-TODAY()),"") | N25: =IFERROR(IF(L25="","",IF(L25<TODAY(),"Expired",IF(L25-TODAY()<=5,"Expiring Soon","Active"))),"")
A26: MLOps | B26: MLOps: NV Contest 2026 June | C26: 46167.875 | D26: 46212.875 | K26: =COUNT(C26,E26,G26,I26) | L26: =IFERROR(MAX(C26:J26),"") | M26: =IFERROR(IF(L26="","",L26-TODAY()),"") | N26: =IFERROR(IF(L26="","",IF(L26<TODAY(),"Expired",IF(L26-TODAY()<=5,"Expiring Soon","Active"))),"")
A27: Natural Language Processing | B27: Natural Language Processing: NV Contest 2026 June | C27: 46167.875 | D27: 46212.875 | K27: =COUNT(C27,E27,G27,I27) | L27: =IFERROR(MAX(C27:J27),"") | M27: =IFERROR(IF(L27="","",L27-TODAY()),"") | N27: =IFERROR(IF(L27="","",IF(L27<TODAY(),"Expired",IF(L27-TODAY()<=5,"Expiring Soon","Active"))),"")
A28: Neural Networks | B28: Neural Networks: NV Contest June 2026 | C28: 46167.875 | D28: 46212.875 | K28: =COUNT(C28,E28,G28,I28) | L28: =IFERROR(MAX(C28:J28),"") | M28: =IFERROR(IF(L28="","",L28-TODAY()),"") | N28: =IFERROR(IF(L28="","",IF(L28<TODAY(),"Expired",IF(L28-TODAY()<=5,"Expiring Soon","Active"))),"")
A29: Product analytics | B29: Product Analytics: NV Contest June 2026 | C29: 46167.875 | D29: 46212.875 | K29: =COUNT(C29,E29,G29,I29) | L29: =IFERROR(MAX(C29:J29),"") | M29: =IFERROR(IF(L29="","",L29-TODAY()),"") | N29: =IFERROR(IF(L29="","",IF(L29<TODAY(),"Expired",IF(L29-TODAY()<=5,"Expiring Soon","Active"))),"")
A30: SQL | B30: SQL: NV Contest 2026 July | C30: 46188.875 | D30: 46203.999 | E30: 46204 | F30: 46218.999 | K30: =COUNT(C30,E30,G30,I30) | L30: =IFERROR(MAX(C30:J30),"") | M30: =IFERROR(IF(L30="","",L30-TODAY()),"") | N30: =IFERROR(IF(L30="","",IF(L30<TODAY(),"Expired",IF(L30-TODAY()<=5,"Expiring Soon","Active"))),"")
A31: Tableau and Excel | B31: Tableau and Excel: NV Contest 2026 July | C31: 46188.875 | D31: 46233.875 | K31: =COUNT(C31,E31,G31,I31) | L31: =IFERROR(MAX(C31:J31),"") | M31: =IFERROR(IF(L31="","",L31-TODAY()),"") | N31: =IFERROR(IF(L31="","",IF(L31<TODAY(),"Expired",IF(L31-TODAY()<=5,"Expiring Soon","Active"))),"")

Sheet DevOps Contests
A1: Batch names | B1: Start Date & Time: | C1: End Date & Time | D1: Attempt 2 Test id | E1: Start Date & Time: | F1: End Date & Time | G1: Attempt 3 test ID | H1: Start Date & Time: | I1: End Date & Time | J1: Attempt 4 Test id | K1: Start Date & Time: | L1: End Date & Time
A2: Data Structure Algorithms 1 : NV Contest Q2 2026 | B2: 13 Apr 2026, Mon, 9:00 pm | C2: 13 May 2026, Wed, 10:30 pm | E2: 13 May 2026, Wed, 12:00 am | F2: 13 Jun 2026, Sat, 12:00 am
A3: Devops: Beginner Python (New) : NV Contest Q2 2026 | B3: 46126.875 | C3: 46156.875
A4: DevOps: Linux 1 : NV Contest Q2 2026 | B4: 26 Apr 2026, Sun, 1:15 pm | C4: 3 May 2026, Sun, 2:15 pm | E4: 5 May 2026, Tue, 12:00 am | F4: 12 May 2026, Tue, 12:00 am
A5: DevOps: Linux 2 : NV Contest Q2 2026 | B5: 26 Apr 2026, Sun, 1:05 pm | C5: 3 May 2026, Sun, 1:05 pm | E5: 15 Apr 2026, Wed, 12:00 am | F5: 22 Apr 2026, Wed, 12:00 am
A6: DevOps: DevOps Tools 1 : NV Contest Q2 2026 | B6: 46126.875 | C6: 46156.958 | E6: 46157 | F6: 46188
A7: DevOps: DevOps Tools 2 : NV Contest Q2 2026 | B7: 46126.875 | C7: 46156.958 | E7: 46157 | F7: 46188 | H7: 46188 | I7: 46218
A8: DevOps: Career Readiness Contest : NV Contest Q2 2026 | B8: 46126.875 | C8: 46156.875
A9: AWS 1 : NV Contest Q2 2026 | B9: Questions arent added yet
A10: AWS 2 : NV Contest Q2 2026 | B10: Questions arent added yet
A11: DevOps: DSA 3 & 4 (New) : NV Contest Q2 2026
A12: DevOps: DSA 4 : NV Contest Q2 2026
A13: Devops: Data Structure Algorithms 2 : NV Contest Q2 2026 | B13: 46126.875 | C13: 46156.938 | E13: 46157 | F13: 46188 | H13: 46188 | I13: 46218 | K13: 46218 | L13: 46249
A14: DevOps: Linux 1 : NV Contests May 2026 | B14: 21 May 2026, Thu, 9:00 pm | C14: 21 May 2026, Thu, 10:00 pm | E14: 22 May 2026, Fri, 12:00 am | F14: 29 May 2026, Fri, 12:00 am
A15: Linux Shell Scripting and Computer Systems 2: NV Contest June 2026 2
A16: Linux Shell Scripting and Computer Systems 1: NV Contest June 2026

Sheet DevOps Contests - In progress
A1: NV DevOps CONTEST
A2: Module Name | B2: Batch Name | C2: Attempt 1 | E2: Attempt 2 | G2: Attempt 3 | I2: Attempt 4 | K2: No. of Attempts | L2: Final Contest Deadline | M2: Days Remaining | N2: Contest Status
C3: Start Date | D3: End Date | E3: Start Date | F3: End Date | G3: Start Date | H3: End Date | I3: Start Date | J3: End Date
A4: AWS 1 | B4: AWS 1 : NV Contest June 2026 | C4: 15 Jun 2026, Mon, 9:00 pm | D4: 30 Jun 2026, Tue, 11:00 pm | E4: 46204 | F4: 46218 | K4: =COUNT(C4,E4,G4,I4) | L4: =IFERROR(MAX(C4:J4),"") | M4: =IFERROR(IF(L4="","",L4-TODAY()),"") | N4: =IFERROR(IF(L4="","",IF(L4<TODAY(),"Expired",IF(L4-TODAY()<=5,"Expiring Soon","Active"))),"")
A5: AWS 2 | B5: AWS 2 : NV Contest June 2026 | K5: =COUNT(C5,E5,G5,I5) | L5: =IFERROR(MAX(C5:J5),"") | M5: =IFERROR(IF(L5="","",L5-TODAY()),"") | N5: =IFERROR(IF(L5="","",IF(L5<TODAY(),"Expired",IF(L5-TODAY()<=5,"Expiring Soon","Active"))),"")
A6: Beginner Python | B6: Devops: Beginner Python : NV Contest June 2026 | K6: =COUNT(C6,E6,G6,I6) | L6: =IFERROR(MAX(C6:J6),"") | M6: =IFERROR(IF(L6="","",L6-TODAY()),"") | N6: =IFERROR(IF(L6="","",IF(L6<TODAY(),"Expired",IF(L6-TODAY()<=5,"Expiring Soon","Active"))),"")
A7: Career Readiness | B7: Career Readiness: NV Contest June 2026 | K7: =COUNT(C7,E7,G7,I7) | L7: =IFERROR(MAX(C7:J7),"") | M7: =IFERROR(IF(L7="","",L7-TODAY()),"") | N7: =IFERROR(IF(L7="","",IF(L7<TODAY(),"Expired",IF(L7-TODAY()<=5,"Expiring Soon","Active"))),"")
A8: Data Structure Algorithms 1 | B8: Data Structure Algorithms 1: NV Contest June 2026 | K8: =COUNT(C8,E8,G8,I8) | L8: =IFERROR(MAX(C8:J8),"") | M8: =IFERROR(IF(L8="","",L8-TODAY()),"") | N8: =IFERROR(IF(L8="","",IF(L8<TODAY(),"Expired",IF(L8-TODAY()<=5,"Expiring Soon","Active"))),"")
A9: Data Structure Algorithms 2 | B9: Data Structure Algorithms 2: NV Contest June 2026
A10: DevOps Tools 1 | B10: DevOps Tools 1: NV Contest June 2026 | K10: =COUNT(C10,E10,G10,I10) | L10: =IFERROR(MAX(C10:J10),"") | M10: =IFERROR(IF(L10="","",L10-TODAY()),"") | N10: =IFERROR(IF(L10="","",IF(L10<TODAY(),"Expired",IF(L10-TODAY()<=5,"Expiring Soon","Active"))),"")
A11: DevOps Tools 2 | B11: DevOps Tools 2: NV Contest June 2026 | K11: =COUNT(C11,E11,G11,I11) | L11: =IFERROR(MAX(C11:J11),"") | M11: =IFERROR(IF(L11="","",L11-TODAY()),"") | N11: =IFERROR(IF(L11="","",IF(L11<TODAY(),"Expired",IF(L11-TODAY()<=5,"Expiring Soon","Active"))),"")
A12: Linux Shell Scripting and Computer Systems 1 | B12: Linux Shell Scripting and Computer Systems 1: NV Contest June 2026 | K12: =COUNT(C12,E12,G12,I12) | L12: =IFERROR(MAX(C12:J12),"") | M12: =IFERROR(IF(L12="","",L12-TODAY()),"") | N12: =IFERROR(IF(L12="","",IF(L12<TODAY(),"Expired",IF(L12-TODAY()<=5,"Expiring Soon","Active"))),"")
A13: Linux Shell Scripting and Computer Systems 2 | B13: Linux Shell Scripting and Computer Systems 2: NV Contest July2026 | K13: =COUNT(C13,E13,G13,I13) | L13: =IFERROR(MAX(C13:J13),"") | M13: =IFERROR(IF(L13="","",L13-TODAY()),"") | N13: =IFERROR(IF(L13="","",IF(L13<TODAY(),"Expired",IF(L13-TODAY()<=5,"Expiring Soon","Active"))),"")

Sheet Academy
A1: Module names | B1: Test ids | C1: Reattempt 1 | D1: Start Date | E1: End date | F1: Extended date 1 | G1: Extended date 2 | H1: Extended date 3 | I1: Total Learners | J1: Not attempted | K1: Learners Attempted | L1: Paased learners | M1: Failed Learners | N1: Attempt(%)
A2: Introduction to Programming (Beginner) 1 | B2: =VLOOKUP(A2,Sheet79!A:G,7,0) | C2: =VLOOKUP(A2,Sheet79!A:H,8,0) | D2: =VLOOKUP(B2,'Academy Raw dump_27June'!B:C,2,0) | E2: =VLOOKUP(B2,'Academy Raw dump_27June'!B:D,3,0) | I2: =K2+J2 | J2: =countifs('Academy Raw dump_27June'!H:H,"Not Attempted",'Academy Raw dump_27June'!E:E,A2) | K2: =COUNTIFS('Academy Raw dump_27June'!H:H,"Attempted",'Academy Raw dump_27June'!E:E,A2) | L2: =COUNTIFS('Academy Raw dump_27June'!I:I,">59",'Academy Raw dump_27June'!E:E,A2) | M2: =K2-L2 | N2: =K2/I2
A3: Introduction to Problem Solving (Intermediate) 2 | B3: =VLOOKUP(A3,Sheet79!A:G,7,0) | C3: =VLOOKUP(A3,Sheet79!A:H,8,0) | D3: =VLOOKUP(B3,'Academy Raw dump_27June'!B:C,2,0) | E3: =VLOOKUP(B3,'Academy Raw dump_27June'!B:D,3,0) | I3: =K3+J3 | J3: =countifs('Academy Raw dump_27June'!H:H,"Not Attempted",'Academy Raw dump_27June'!E:E,A3) | K3: =COUNTIFS('Academy Raw dump_27June'!H:H,"Attempted",'Academy Raw dump_27June'!E:E,A3) | L3: =COUNTIFS('Academy Raw dump_27June'!I:I,">59",'Academy Raw dump_27June'!E:E,A3) | M3: =K3-L3 | N3: =K3/I3
A4: Backend LLD and Development 3 | B4: =VLOOKUP(A4,Sheet79!A:G,7,0) | C4: =VLOOKUP(A4,Sheet79!A:H,8,0) | D4: =VLOOKUP(B4,'Academy Raw dump_27June'!B:C,2,0) | E4: =VLOOKUP(B4,'Academy Raw dump_27June'!B:D,3,0) | I4: =K4+J4 | J4: =countifs('Academy Raw dump_27June'!H:H,"Not Attempted",'Academy Raw dump_27June'!E:E,A4) | K4: =COUNTIFS('Academy Raw dump_27June'!H:H,"Attempted",'Academy Raw dump_27June'!E:E,A4) | L4: =COUNTIFS('Academy Raw dump_27June'!I:I,">59",'Academy Raw dump_27June'!E:E,A4) | M4: =K4-L4 | N4: =K4/I4
A5: DSA for Competitive Programming | B5: =VLOOKUP(A5,Sheet79!A:G,7,0) | C5: =VLOOKUP(A5,Sheet79!A:H,8,0) | D5: =VLOOKUP(B5,'Academy Raw dump_27June'!B:C,2,0) | E5: =VLOOKUP(B5,'Academy Raw dump_27June'!B:D,3,0) | I5: =K5+J5 | J5: =countifs('Academy Raw dump_27June'!H:H,"Not Attempted",'Academy Raw dump_27June'!E:E,A5) | K5: =COUNTIFS('Academy Raw dump_27June'!H:H,"Attempted",'Academy Raw dump_27June'!E:E,A5) | L5: =COUNTIFS('Academy Raw dump_27June'!I:I,">59",'Academy Raw dump_27June'!E:E,A5) | M5: =K5-L5 | N5: =K5/I5
A6: Computer Systems and Fundamentals | B6: =VLOOKUP(A6,Sheet79!A:G,7,0) | C6: =VLOOKUP(A6,Sheet79!A:H,8,0) | D6: =VLOOKUP(B6,'Academy Raw dump_27June'!B:C,2,0) | E6: =VLOOKUP(B6,'Academy Raw dump_27June'!B:D,3,0) | I6: =K6+J6 | J6: =countifs('Academy Raw dump_27June'!H:H,"Not Attempted",'Academy Raw dump_27June'!E:E,A6) | K6: =COUNTIFS('Academy Raw dump_27June'!H:H,"Attempted",'Academy Raw dump_27June'!E:E,A6) | L6: =COUNTIFS('Academy Raw dump_27June'!I:I,">59",'Academy Raw dump_27June'!E:E,A6) | M6: =K6-L6 | N6: =K6/I6
A7: Advanced DSA 4 | B7: =VLOOKUP(A7,Sheet79!A:G,7,0) | C7: =VLOOKUP(A7,Sheet79!A:H,8,0) | D7: =VLOOKUP(B7,'Academy Raw dump_27June'!B:C,2,0) | E7: =VLOOKUP(B7,'Academy Raw dump_27June'!B:D,3,0) | I7: =K7+J7 | J7: =countifs('Academy Raw dump_27June'!H:H,"Not Attempted",'Academy Raw dump_27June'!E:E,A7) | K7: =COUNTIFS('Academy Raw dump_27June'!H:H,"Attempted",'Academy Raw dump_27June'!E:E,A7) | L7: =COUNTIFS('Academy Raw dump_27June'!I:I,">59",'Academy Raw dump_27June'!E:E,A7) | M7: =K7-L7 | N7: =K7/I7
A8: Full-stack LLD and Development 1 | B8: =VLOOKUP(A8,Sheet79!A:G,7,0) | C8: =VLOOKUP(A8,Sheet79!A:H,8,0) | D8: =VLOOKUP(B8,'Academy Raw dump_27June'!B:C,2,0) | E8: =VLOOKUP(B8,'Academy Raw dump_27June'!B:D,3,0) | I8: =K8+J8 | J8: =countifs('Academy Raw dump_27June'!H:H,"Not Attempted",'Academy Raw dump_27June'!E:E,A8) | K8: =COUNTIFS('Academy Raw dump_27June'!H:H,"Attempted",'Academy Raw dump_27June'!E:E,A8) | L8: =COUNTIFS('Academy Raw dump_27June'!I:I,">59",'Academy Raw dump_27June'!E:E,A8) | M8: =K8-L8 | N8: =K8/I8
A9: Advanced DSA 1 | B9: =VLOOKUP(A9,Sheet79!A:G,7,0) | C9: =VLOOKUP(A9,Sheet79!A:H,8,0) | D9: =VLOOKUP(B9,'Academy Raw dump_27June'!B:C,2,0) | E9: =VLOOKUP(B9,'Academy Raw dump_27June'!B:D,3,0) | I9: =K9+J9 | J9: =countifs('Academy Raw dump_27June'!H:H,"Not Attempted",'Academy Raw dump_27June'!E:E,A9) | K9: =COUNTIFS('Academy Raw dump_27June'!H:H,"Attempted",'Academy Raw dump_27June'!E:E,A9) | L9: =COUNTIFS('Academy Raw dump_27June'!I:I,">59",'Academy Raw dump_27June'!E:E,A9) | M9: =K9-L9 | N9: =K9/I9
A10: Backend LLD and Development 2 | B10: =VLOOKUP(A10,Sheet79!A:G,7,0) | C10: =VLOOKUP(A10,Sheet79!A:H,8,0) | D10: =VLOOKUP(B10,'Academy Raw dump_27June'!B:C,2,0) | E10: =VLOOKUP(B10,'Academy Raw dump_27June'!B:D,3,0) | I10: =K10+J10 | J10: =countifs('Academy Raw dump_27June'!H:H,"Not Attempted",'Academy Raw dump_27June'!E:E,A10) | K10: =COUNTIFS('Academy Raw dump_27June'!H:H,"Attempted",'Academy Raw dump_27June'!E:E,A10) | L10: =COUNTIFS('Academy Raw dump_27June'!I:I,">59",'Academy Raw dump_27June'!E:E,A10) | M10: =K10-L10 | N10: =K10/I10
A11: Introduction to Problem Solving (Intermediate) 1 | B11: =VLOOKUP(A11,Sheet79!A:G,7,0) | C11: =VLOOKUP(A11,Sheet79!A:H,8,0) | D11: =VLOOKUP(B11,'Academy Raw dump_27June'!B:C,2,0) | E11: =VLOOKUP(B11,'Academy Raw dump_27June'!B:D,3,0) | I11: =K11+J11 | J11: =countifs('Academy Raw dump_27June'!H:H,"Not Attempted",'Academy Raw dump_27June'!E:E,A11) | K11: =COUNTIFS('Academy Raw dump_27June'!H:H,"Attempted",'Academy Raw dump_27June'!E:E,A11) | L11: =COUNTIFS('Academy Raw dump_27June'!I:I,">59",'Academy Raw dump_27June'!E:E,A11) | M11: =K11-L11 | N11: =K11/I11
A12: Full-stack LLD and Development 3 | B12: =VLOOKUP(A12,Sheet79!A:G,7,0) | C12: =VLOOKUP(A12,Sheet79!A:H,8,0) | D12: =VLOOKUP(B12,'Academy Raw dump_27June'!B:C,2,0) | E12: =VLOOKUP(B12,'Academy Raw dump_27June'!B:D,3,0) | I12: =K12+J12 | J12: =countifs('Academy Raw dump_27June'!H:H,"Not Attempted",'Academy Raw dump_27June'!E:E,A12) | K12: =COUNTIFS('Academy Raw dump_27June'!H:H,"Attempted",'Academy Raw dump_27June'!E:E,A12) | L12: =COUNTIFS('Academy Raw dump_27June'!I:I,">59",'Academy Raw dump_27June'!E:E,A12) | M12: =K12-L12 | N12: =K12/I12
A13: High Level Design | B13: =VLOOKUP(A13,Sheet79!A:G,7,0) | C13: =VLOOKUP(A13,Sheet79!A:H,8,0) | D13: =VLOOKUP(B13,'Academy Raw dump_27June'!B:C,2,0) | E13: =VLOOKUP(B13,'Academy Raw dump_27June'!B:D,3,0) | I13: =K13+J13 | J13: =countifs('Academy Raw dump_27June'!H:H,"Not Attempted",'Academy Raw dump_27June'!E:E,A13) | K13: =COUNTIFS('Academy Raw dump_27June'!H:H,"Attempted",'Academy Raw dump_27June'!E:E,A13) | L13: =COUNTIFS('Academy Raw dump_27June'!I:I,">59",'Academy Raw dump_27June'!E:E,A13) | M13: =K13-L13 | N13: =K13/I13
